Workbook

Sheet Summary 
A1: Project: | C1: ='Landscape R01'!D4 -> BELMORE RESIDENCES 305 Plot No. 6110305, Bukadra, Dubai, United Arab Emirates @Ras Al Khor | Q1: ='Landscape R01'!BK4 -> 46160
A2: Project Code: | C2: BELMORE RESIDENCES 305 | P2: Ref: | Q2: ='Landscape R01'!AZ4 &" - "&'Landscape R01'!BL4 -> CS/HO/PROC/P1026/CIV/26/12 - REV-0
A3: Client Name: | C3: M/s Ellington Properties Developments LLC
A4: Consultant: | C4: Kling Consult GMBH - Dubai
A5: Package Name: | C5: ='Landscape R01'!E2 -> COMPARISON STATEMENT FOR LANDSCAPING WORKS (SUPPLY & INSTALLATION)
A6: Bid Summary
A8: Sl No. | B8: Description | C8: Vendor Name | D8: Amount | J8: Payment Terms | N8: Securities | P8: Technical Compliance (Yes/No) | Q8: Remarks
D9: Rev 00 | E9: Rev 01 | F9: Rev 02 | G9: Rev 03 | H9: Rev 04 | I9: Final Offer | J9: Advance | K9: MOS | L9: Progress | M9: Retention | N9: Advance Guarantee / Cheque | O9: Performance Bond / Cheque
A10: 1 | B10: Lowest Vendor | C10: ='Landscape R01'!AF5 -> Green dunes | D10: ='Landscape R01'!AH130 -> 2272085.6 | E10: ='Landscape R01'!AJ130 -> 0 | I10: =D10 -> 2272085.6 | J10: 0.1 | K10: 0.5 | L10: 0.4 | M10: 0.1 | N10: SC | O10: 10% SC | P10: ='Landscape R01'!AF145 -> 0 | Q10: ='Landscape R01'!AI9 -> 0 | S10: =$D$26 -> 2189273.1 | T10: =IF(H10=0,G10,IF(G10=0,F10,IF(E10=0,D10,H10))) -> 0
A11: 2 | B11: 2nd Lowest | C11: ='Landscape R01'!Q5 -> Premier Irrigation & Landscaping L.L.C | D11: ='Landscape R01'!R130 -> 2379630.3 | E11: ='Landscape R01'!T130 -> 0 | I11: =D11 -> 2379630.3 | J11: 0.1 | L11: 0.9 | M11: 0.1 | N11: SC | O11: 10% SC | P11: ='Landscape R01'!Q145 -> 0 | Q11: ='Landscape R01'!S9 -> 0 | S11: =$D$26 -> 2189273.1
A12: 3 | B12: 3rd Lowest | C12: ='Landscape R01'!U5 -> Planta Lanndscaping & Irrigation L.L.C | D12: ='Landscape R01'!W130 -> 2816733 | E12: ='Landscape R01'!Y130 -> 0 | F12: ='Landscape R01'!AA130 -> 0 | G12: ='Landscape R01'!AC130 -> 0 | H12: ='Landscape R01'!AE130 -> 0 | I12: =D12 -> 2816733 | P12: ='Landscape R01'!U145 -> 0 | Q12: ='Landscape R01'!AD9 -> 0 | S12: =$D$26 -> 2189273.1
A13: 4 | B13: 4th Lowest | C13: ='Landscape R01'!H5 -> KTC INTERNATIONAL LANDSCAPING LLC | D13: ='Landscape R01'!J130 -> 3866696 | E13: ='Landscape R01'!L130 -> 0 | F13: ='Landscape R01'!P130 -> 0 | G13: ='Landscape R01'!N130 -> 0 | H13: =IF(H13=0,G13,IF(G13=0,IF(E13=0,D13,H13))) -> 0 | I13: =D13 -> 3866696 | K13: 0.5 | L13: 0.5 | M13: 0.1 | N13: NA | O13: 10%SC | P13: 20 Years - 359,228.02 25 years - 395,150.82 | Q13: ='Landscape R01'!O9 -> 0 | S13: =$D$26 -> 2189273.1
A14: 5 | B14: 5th Lowest | C14: ='Landscape R01'!AK5 -> 0 | D14: ='Landscape R01'!AL130 -> 0 | E14: ='Landscape R01'!AN130 -> 0 | F14: ='Landscape R01'!AP130 -> 0 | G14: ='Landscape R01'!AT130 -> 0 | H14: ='Landscape R01'!AR130 -> 0 | I14: ='Landscape R01'!AT130 -> 0 | P14: 20 Years - 456.979.71 25 years - 677,066.21 | Q14: ='Landscape R01'!AS9 -> 0 | S14: =$D$26 -> 2189273.1
A15: 6 | B15: 6th Lowest | C15: ='Landscape R01'!AU5 -> 0 | D15: ='Landscape R01'!AV130 -> 0 | E15: ='Landscape R01'!AX130 -> 0 | F15: ='Landscape R01'!AZ130 -> 0 | I15: =E15 -> 0 | J15: 0.1 | L15: 0.9 | M15: 0.1 | N15: BG | O15: 10% BG | P15: 20 Years - 464.231.34 25 years - 616,235.84 | Q15: ='Landscape R01'!AY9 -> 0 | S15: =$D$26 -> 2189273.1
A16: 7 | B16: 7th Lowest | C16: ='Landscape R01'!BA5 -> 0 | D16: ='Landscape R01'!BB130 -> 0 | E16: ='Landscape R01'!BD130 -> 0 | F16: ='Landscape R01'!BF130 -> 0 | I16: =F16 -> 0 | J16: 0.1 | K16: 0.4 | L16: 0.5 | M16: 0.1 | N16: SC | O16: 10% sc | P16: ='Landscape R01'!BA145 -> 0 | Q16: ='Landscape R01'!BE9 -> 0 | S16: =$D$26 -> 2189273.1
A17: 8 | B17: 8th Lowest | C17: ='Landscape R01'!BG5 -> 0 | D17: ='Landscape R01'!BH130 -> 0 | E17: ='Landscape R01'!BJ130 -> 0 | F17: ='Landscape R01'!BL130 -> 0 | I17: =F17 -> 0 | P17: ='Landscape R01'!BG145 -> 0 | Q17: ='Landscape R01'!BK9 -> 0 | S17: =$D$26 -> 2189273.1
A18: 7 | B18: 7th Lowest | C18: =[2]BidTab2!B13 -> 0 | I18: =VLOOKUP(C18,[2]BidTab2!B13:L21,5,FALSE) -> 0 | P18: =RIGHT([2]BidTab2!A10,16)
A19: 8 | B19: 8th Lowest | C19: =[2]BidTab2!B14 -> 0 | I19: =VLOOKUP(C19,[2]BidTab2!B14:L22,5,FALSE) -> 0 | P19: =RIGHT([2]BidTab2!A8,16)
A20: 9 | B20: 9th Lowest | C20: =[2]BidTab2!B15 -> 0 | I20: =VLOOKUP(C20,[2]BidTab2!B15:L23,5,FALSE) -> 0 | P20: =RIGHT([2]BidTab2!A9,16)
N21: Refer Bid Tab for details
B22: Recommended Vendor: | D22: =C10 -> Green dunes
B23: Back Up Vendor:
D25: Budget | E25: Selling
A26: Allowance | D26: ='Landscape R01'!G130 -> 2189273.1
A27: Order Value | D27: =I10 -> 2272085.6
A28: Profit/(Loss) | D28: =D26-D27 -> -82812.456 | E28: =E26-E27 -> 0
A30: NOTES | C30: Specified Material : | D30: ='Landscape R01'!U132 -> 0
C31: Warranty as per specs | D31: Warranty Substructure(20 years and extended warranty 25 years)

Sheet Landscape R01
E2: COMPARISON STATEMENT FOR LANDSCAPING WORKS (SUPPLY & INSTALLATION)
C4: Project Name: | D4: BELMORE RESIDENCES 305 Plot No. 6110305, Bukadra, Dubai, United Arab Emirates @Ras Al Khor | AY4: DOC Ref: | AZ4: CS/HO/PROC/P1026/CIV/26/12 | BJ4: DATE | BK4: 46160 | BL4: REV-0
B5: Sno | C5: Description | D5: Unit | H5: KTC INTERNATIONAL LANDSCAPING LLC | Q5: Premier Irrigation & Landscaping L.L.C | U5: Planta Lanndscaping & Irrigation L.L.C | AF5: Green dunes
E6: Quantity | F6: BCC Rate | G6: BCC Budget | H6: Naseek Erikunnan (971-5811 98257) naseek.erikunnan@ktcco.net | Q6: 971 55 995 0883 | U6: 971 55 842 7100 | AF6: Suhesh 971 52 123 5179
H7: KTCL/EQ25/255/R04 | Q7: KTCL/EQ25/263/R01 | U7: PLA/QTN/1025/1603_R02 | AF7: GD060/QTN/2026/0060
H8: 46161 | Q8: 46162 | U8: 46167 | AF8: 46179
H9: Remeasureable | Q9: Remeasureable | U9: Lumpsum | AF9: Lumpsum
H11: R0 Price | I11: Qty | J11: R0 Amount | K11: R1 Price | L11: R1 Amount | M11: R1 Price | N11: R1 Amount | O11: R1 Price | P11: R1 Amount | Q11: R0 Price | R11: R0 Amount | S11: R1 Price | T11: R1 Amount | U11: R0 Price | W11: R0 Amount | X11: R1 Price | Y11: R1 Amount | Z11: R2 Price | AA11: R2 Amount | AB11: R2 Price | AC11: R2 Amount | AD11: R2 Price | AE11: R2 Amount | AF11: R0 Price | AH11: R0 Amount | AI11: R1 Price | AJ11: R1 Amount | AK11: R0 Price | AL11: R0 Amount | AM11: R1 Price | AN11: R1 Amount | AO11: R2 Price | AP11: R2 Amount | AQ11: R3 Price | AR11: R3 Amount | AS11: R3 Price | AT11: R3 Amount | AU11: R0 Price | AV11: R0 Amount | AW11: R1 Price | AX11: R1 Amount | AY11: R1 Price | AZ11: R1 Amount | BA11: R0 Price | BB11: R0 Amount | BC11: R1 Price | BD11: R1 Amount | BE11: R2 Price | BF11: R2 Amount | BG11: R0 Price | BH11: R0 Amount | BI11: R1 Price | BJ11: R1 Amount | BK11: R2 Price | BL11: R2 Amount
C12: HARDSCAPE | BK12: unbonded
B13: =IF(ISBLANK($E13)," ",IF(AND(COUNTA(E$8:$E13)+64>72,COUNTA(E$8:$E13)+64<78),CHAR(COUNTA(E$8:$E13)+65),IF(COUNTA(E$8:$E13)+64>77,CHAR(COUNTA(E$8:$E13)+66),CHAR(COUNTA(E$8:$E13)+64)))) | C13: EXTERNAL WORKS
B14: =IF(ISBLANK($E14)," ",IF(AND(COUNTA(E$8:$E14)+64>72,COUNTA(E$8:$E14)+64<78),CHAR(COUNTA(E$8:$E14)+65),IF(COUNTA(E$8:$E14)+64>77,CHAR(COUNTA(E$8:$E14)+66),CHAR(COUNTA(E$8:$E14)+64)))) | C14: The Contractor is referred to the specifications and drawings for the details related to the works under this division and he is to include for complying with all the requirements contained therein, whether or not they are specifically mentioned within the Item.
B15: =IF(ISBLANK($E15)," ",IF(AND(COUNTA(E$8:$E15)+64>72,COUNTA(E$8:$E15)+64<78),CHAR(COUNTA(E$8:$E15)+65),IF(COUNTA(E$8:$E15)+64>77,CHAR(COUNTA(E$8:$E15)+66),CHAR(COUNTA(E$8:$E15)+64)))) | C15: External Floor Finishes
B16: =IF(ISBLANK($E16)," ",IF(AND(COUNTA(E$8:$E16)+64>72,COUNTA(E$8:$E16)+64<78),CHAR(COUNTA(E$8:$E16)+65),IF(COUNTA(E$8:$E16)+64>77,CHAR(COUNTA(E$8:$E16)+66),CHAR(COUNTA(E$8:$E16)+64)))) | C16: HARDSCAPE
C17: Supply and installation of hardscape including all necessary excavation and filling as required, sub base, screed, bedding materials, support, adhesives,grouts, spacers, trims, dividing strips (where applicable) and fixing accessories ..etc, all in accordance with Drawings, Specifications and to the Engineer's approval
B18: =IF(ISBLANK($E18)," ",IF(AND(COUNTA(E$8:$E18)+64>72,COUNTA(E$8:$E18)+64<78),CHAR(COUNTA(E$8:$E18)+65),IF(COUNTA(E$8:$E18)+64>77,CHAR(COUNTA(E$8:$E18)+66),CHAR(COUNTA(E$8:$E18)+64)))) -> A | C18: PA-01A - Concrete pavers 600x600x80mm | D18: m2 | E18: 5 | F18: 217.8 | G18: 1607.364 | H18: 534 | I18: 5 | J18: =H18*$I18 -> 2670 | L18: =K18*$E18 -> 0 | N18: =M18*$E18 -> 0 | P18: =O18*$E18 -> 0 | Q18: 280 | R18: =Q18*$E18 -> 1400 | T18: =S18*$E18 -> 0 | U18: 274 | V18: 177 | W18: =V18*U18 -> 48498 | Y18: =X18*$E18 -> 0 | AA18: =Z18*$E18 -> 0 | AC18: =AB18*$E18 -> 0 | AE18: =AD18*$E18 -> 0 | AF18: 226 | AG18: 178 | AH18: =AF18*$AG18 -> 40228 | AJ18: =AI18*$E18 -> 0 | AL18: =AK18*$E18 -> 0 | AN18: =AM18*$E18 -> 0 | AP18: =AO18*$E18 -> 0 | AR18: =AQ18*$E18 -> 0 | AT18: =AS18*$E18 -> 0 | AV18: =AU18*$E18 -> 0 | AX18: =AW18*$E18 -> 0 | AZ18: =AY18*$E18 -> 0 | BB18: =BA18*$E18 -> 0 | BD18: =BC18*$E18 -> 0 | BF18: =BE18*$E18 -> 0 | BH18: =BG18*$E18 -> 0 | BJ18: =BI18*$E18 -> 0 | BL18: =BK18*$E18 -> 0
B19: =IF(ISBLANK($E19)," ",IF(AND(COUNTA(E$8:$E19)+64>72,COUNTA(E$8:$E19)+64<78),CHAR(COUNTA(E$8:$E19)+65),IF(COUNTA(E$8:$E19)+64>77,CHAR(COUNTA(E$8:$E19)+66),CHAR(COUNTA(E$8:$E19)+64)))) -> B | C19: PA-01B - Concrete pavers 300x300x80mm | D19: m2 | E19: 2 | F19: 217.8 | G19: 1960.2 | H19: 534 | I19: 2 | J19: =H19*$I19 -> 1068 | L19: =K19*$E19 -> 0 | N19: =M19*$E19 -> 0 | P19: =O19*$E19 -> 0 | Q19: 245 | R19: =Q19*$E19 -> 490 | T19: =S19*$E19 -> 0 | U19: 274 | V19: 9 | W19: =V19*U19 -> 2466 | Y19: =X19*$E19 -> 0 | AA19: =Z19*$E19 -> 0 | AC19: =AB19*$E19 -> 0 | AE19: =AD19*$E19 -> 0 | AF19: 226 | AG19: 2 | AH19: =AF19*$AG19 -> 452 | AJ19: =AI19*$E19 -> 0 | AL19: =AK19*$E19 -> 0 | AN19: =AM19*$E19 -> 0 | AP19: =AO19*$E19 -> 0 | AR19: =AQ19*$E19 -> 0 | AT19: =AS19*$E19 -> 0 | AV19: =AU19*$E19 -> 0 | AX19: =AW19*$E19 -> 0 | AZ19: =AY19*$E19 -> 0 | BB19: =BA19*$E19 -> 0 | BD19: =BC19*$E19 -> 0 | BF19: =BE19*$E19 -> 0 | BH19: =BG19*$E19 -> 0 | BJ19: =BI19*$E19 -> 0 | BL19: =BK19*$E19 -> 0
B20: =IF(ISBLANK($E20)," ",IF(AND(COUNTA(E$8:$E20)+64>72,COUNTA(E$8:$E20)+64<78),CHAR(COUNTA(E$8:$E20)+65),IF(COUNTA(E$8:$E20)+64>77,CHAR(COUNTA(E$8:$E20)+66),CHAR(COUNTA(E$8:$E20)+64)))) -> C | C20: PA-01C - Concrete pavers 300x300x80mm | D20: m2 | E20: 7 | F20: 217.8 | G20: 3702.6 | H20: 534 | I20: 7 | J20: =H20*$I20 -> 3738 | L20: =K20*$E20 -> 0 | N20: =M20*$E20 -> 0 | P20: =O20*$E20 -> 0 | Q20: 245 | R20: =Q20*$E20 -> 1715 | T20: =S20*$E20 -> 0 | U20: 274 | V20: 17 | W20: =V20*U20 -> 4658 | Y20: =X20*$E20 -> 0 | AA20: =Z20*$E20 -> 0 | AC20: =AB20*$E20 -> 0 | AE20: =AD20*$E20 -> 0 | AF20: 226 | AG20: 7 | AH20: =AF20*$AG20 -> 1582 | AJ20: =AI20*$E20 -> 0 | AL20: =AK20*$E20 -> 0 | AN20: =AM20*$E20 -> 0 | AP20: =AO20*$E20 -> 0 | AR20: =AQ20*$E20 -> 0 | AT20: =AS20*$E20 -> 0 | AV20: =AU20*$E20 -> 0 | AX20: =AW20*$E20 -> 0 | AZ20: =AY20*$E20 -> 0 | BB20: =BA20*$E20 -> 0 | BD20: =BC20*$E20 -> 0 | BF20: =BE20*$E20 -> 0 | BH20: =BG20*$E20 -> 0 | BJ20: =BI20*$E20 -> 0 | BL20: =BK20*$E20 -> 0
B21: =IF(ISBLANK($E21)," ",IF(AND(COUNTA(E$8:$E21)+64>72,COUNTA(E$8:$E21)+64<78),CHAR(COUNTA(E$8:$E21)+65),IF(COUNTA(E$8:$E21)+64>77,CHAR(COUNTA(E$8:$E21)+66),CHAR(COUNTA(E$8:$E21)+64)))) -> D | C21: PA-02A - Porcelain tile 600x1200x10mm | D21: m2 | E21: 343 | F21: 233.1 | G21: 79953.3 | H21: 613 | I21: 343 | J21: =H21*$I21 -> 210259 | L21: =K21*$E21 -> 0 | N21: =M21*$E21 -> 0 | P21: =O21*$E21 -> 0 | Q21: 380 | R21: =Q21*$E21 -> 130340 | T21: =S21*$E21 -> 0 | U21: 294 | V21: 360 | W21: =V21*U21 -> 105840 | Y21: =X21*$E21 -> 0 | AA21: =Z21*$E21 -> 0 | AC21: =AB21*$E21 -> 0 | AE21: =AD21*$E21 -> 0 | AF21: 446 | AG21: 343 | AH21: =AF21*$AG21 -> 152978 | AJ21: =AI21*$E21 -> 0 | AL21: =AK21*$E21 -> 0 | AN21: =AM21*$E21 -> 0 | AP21: =AO21*$E21 -> 0 | AR21: =AQ21*$E21 -> 0 | AT21: =AS21*$E21 -> 0 | AV21: =AU21*$E21 -> 0 | AX21: =AW21*$E21 -> 0 | AZ21: =AY21*$E21 -> 0 | BB21: =BA21*$E21 -> 0 | BD21: =BC21*$E21 -> 0 | BF21: =BE21*$E21 -> 0 | BH21: =BG21*$E21 -> 0 | BJ21: =BI21*$E21 -> 0 | BL21: =BK21*$E21 -> 0
B22: =IF(ISBLANK($E22)," ",IF(AND(COUNTA(E$8:$E22)+64>72,COUNTA(E$8:$E22)+64<78),CHAR(COUNTA(E$8:$E22)+65),IF(COUNTA(E$8:$E22)+64>77,CHAR(COUNTA(E$8:$E22)+66),CHAR(COUNTA(E$8:$E22)+64)))) -> E | C22: PA-02B - Pool Porcelain tile 600x300x10mm (L05 - Adults and Kids pool) | D22: m2 | E22: 426 | F22: 65.7 | G22: 27988.2 | H22: 604 | I22: 426 | J22: =H22*$I22 -> 257304 | L22: =K22*$E22 -> 0 | N22: =M22*$E22 -> 0 | P22: =O22*$E22 -> 0 | Q22: 380 | R22: =Q22*$E22 -> 161880 | T22: =S22*$E22 -> 0 | V22: 426 | W22: =V22*U22 -> 0 | Y22: =X22*$E22 -> 0 | AA22: =Z22*$E22 -> 0 | AC22: =AB22*$E22 -> 0 | AE22: =AD22*$E22 -> 0 | AG22: 426 | AH22: =AF22*$AG22 -> 0 | AJ22: =AI22*$E22 -> 0 | AL22: =AK22*$E22 -> 0 | AN22: =AM22*$E22 -> 0 | AP22: =AO22*$E22 -> 0 | AR22: =AQ22*$E22 -> 0 | AT22: =AS22*$E22 -> 0 | AV22: =AU22*$E22 -> 0 | AX22: =AW22*$E22 -> 0 | AZ22: =AY22*$E22 -> 0 | BB22: =BA22*$E22 -> 0 | BD22: =BC22*$E22 -> 0 | BF22: =BE22*$E22 -> 0 | BH22: =BG22*$E22 -> 0 | BJ22: =BI22*$E22 -> 0 | BL22: =BK22*$E22 -> 0
B23: =IF(ISBLANK($E23)," ",IF(AND(COUNTA(E$8:$E23)+64>72,COUNTA(E$8:$E23)+64<78),CHAR(COUNTA(E$8:$E23)+65),IF(COUNTA(E$8:$E23)+64>77,CHAR(COUNTA(E$8:$E23)+66),CHAR(COUNTA(E$8:$E23)+64)))) -> F | C23: PA-02C - Porcelain tile 600x1200x9mm (L05 - Paving) | D23: m2 | E23: 454 | F23: 233.1 | G23: 110955.6 | H23: 656 | I23: 454 | J23: =H23*$I23 -> 297824 | L23: =K23*$E23 -> 0 | N23: =M23*$E23 -> 0 | P23: =O23*$E23 -> 0 | Q23: 380 | R23: =Q23*$E23 -> 172520 | T23: =S23*$E23 -> 0 | U23: 294 | V23: 476 | W23: =V23*U23 -> 139944 | Y23: =X23*$E23 -> 0 | AA23: =Z23*$E23 -> 0 | AC23: =AB23*$E23 -> 0 | AE23: =AD23*$E23 -> 0 | AF23: 466 | AG23: 454 | AH23: =AF23*$AG23 -> 211564 | AJ23: =AI23*$E23 -> 0 | AL23: =AK23*$E23 -> 0 | AN23: =AM23*$E23 -> 0 | AP23: =AO23*$E23 -> 0 | AR23: =AQ23*$E23 -> 0 | AT23: =AS23*$E23 -> 0 | AV23: =AU23*$E23 -> 0 | AX23: =AW23*$E23 -> 0 | AZ23: =AY23*$E23 -> 0 | BB23: =BA23*$E23 -> 0 | BD23: =BC23*$E23 -> 0 | BF23: =BE23*$E23 -> 0 | BH23: =BG23*$E23 -> 0 | BJ23: =BI23*$E23 -> 0 | BL23: =BK23*$E23 -> 0
B24: =IF(ISBLANK($E24)," ",IF(AND(COUNTA(E$8:$E24)+64>72,COUNTA(E$8:$E24)+64<78),CHAR(COUNTA(E$8:$E24)+65),IF(COUNTA(E$8:$E24)+64>77,CHAR(COUNTA(E$8:$E24)+66),CHAR(COUNTA(E$8:$E24)+64)))) -> G | C24: PA-02D - Porcelain tile 600x600x10mm (L05 - Seating pods paving and BBQ counter cladding) | D24: m2 | E24: 20 | F24: 233.1 | G24: 4662 | H24: 656 | I24: 20 | J24: =H24*$I24 -> 13120 | L24: =K24*$E24 -> 0 | N24: =M24*$E24 -> 0 | P24: =O24*$E24 -> 0 | Q24: 380 | R24: =Q24*$E24 -> 7600 | T24: =S24*$E24 -> 0 | U24: 294 | V24: 20 | W24: =V24*U24 -> 5880 | Y24: =X24*$E24 -> 0 | AA24: =Z24*$E24 -> 0 | AC24: =AB24*$E24 -> 0 | AE24: =AD24*$E24 -> 0 | AF24: 362 | AG24: 20 | AH24: =AF24*$AG24 -> 7240 | AJ24: =AI24*$E24 -> 0 | AL24: =AK24*$E24 -> 0 | AN24: =AM24*$E24 -> 0 | AP24: =AO24*$E24 -> 0 | AR24: =AQ24*$E24 -> 0 | AT24: =AS24*$E24 -> 0 | AV24: =AU24*$E24 -> 0 | AX24: =AW24*$E24 -> 0 | AZ24: =AY24*$E24 -> 0 | BB24: =BA24*$E24 -> 0 | BD24: =BC24*$E24 -> 0 | BF24: =BE24*$E24 -> 0 | BH24: =BG24*$E24 -> 0 | BJ24: =BI24*$E24 -> 0 | BL24: =BK24*$E24 -> 0
B25: =IF(ISBLANK($E25)," ",IF(AND(COUNTA(E$8:$E25)+64>72,COUNTA(E$8:$E25)+64<78),CHAR(COUNTA(E$8:$E25)+65),IF(COUNTA(E$8:$E25)+64>77,CHAR(COUNTA(E$8:$E25)+66),CHAR(COUNTA(E$8:$E25)+64)))) -> H | C25: PA-02E - Natural stone coping 600x300x30mm (L05 - Pool Edge Coping) | D25: m2 | E25: 17 | F25: 435.6 | G25: 7405.2 | H25: 1002 | I25: 17 | J25: =H25*$I25 -> 17034 | L25: =K25*$E25 -> 0 | N25: =M25*$E25 -> 0 | P25: =O25*$E25 -> 0 | Q25: 620 | R25: =Q25*$E25 -> 10540 | T25: =S25*$E25 -> 0 | U25: 658 | V25: 17 | W25: =V25*U25 -> 11186 | Y25: =X25*$E25 -> 0 | AA25: =Z25*$E25 -> 0 | AC25: =AB25*$E25 -> 0 | AE25: =AD25*$E25 -> 0 | AH25: =AF25*$AG25 -> 0 | AJ25: =AI25*$E25 -> 0 | AL25: =AK25*$E25 -> 0 | AN25: =AM25*$E25 -> 0 | AP25: =AO25*$E25 -> 0 | AR25: =AQ25*$E25 -> 0 | AT25: =AS25*$E25 -> 0 | AV25: =AU25*$E25 -> 0 | AX25: =AW25*$E25 -> 0 | AZ25: =AY25*$E25 -> 0 | BB25: =BA25*$E25 -> 0 | BD25: =BC25*$E25 -> 0 | BF25: =BE25*$E25 -> 0 | BH25: =BG25*$E25 -> 0 | BJ25: =BI25*$E25 -> 0 | BL25: =BK25*$E25 -> 0
B26: =IF(ISBLANK($E26)," ",IF(AND(COUNTA(E$8:$E26)+64>72,COUNTA(E$8:$E26)+64<78),CHAR(COUNTA(E$8:$E26)+65),IF(COUNTA(E$8:$E26)+64>77,CHAR(COUNTA(E$8:$E26)+66),CHAR(COUNTA(E$8:$E26)+64)))) -> J | C26: PA-02F - Porcelain grating tile 600x300x20mm (L05 - BMU mound path along the kids play area ) | D26: m2 | E26: 15 | F26: 288 | G26: 4320 | H26: 890 | I26: 15 | J26: =H26*$I26 -> 13350 | L26: =K26*$E26 -> 0 | N26: =M26*$E26 -> 0 | P26: =O26*$E26 -> 0 | Q26: 425 | R26: =Q26*$E26 -> 6375 | T26: =S26*$E26 -> 0 | U26: 411 | V26: 15 | W26: =V26*U26 -> 6165 | Y26: =X26*$E26 -> 0 | AA26: =Z26*$E26 -> 0 | AC26: =AB26*$E26 -> 0 | AE26: =AD26*$E26 -> 0 | AF26: 656 | AG26: 15 | AH26: =AF26*$AG26 -> 9840 | AJ26: =AI26*$E26 -> 0 | AL26: =AK26*$E26 -> 0 | AN26: =AM26*$E26 -> 0 | AP26: =AO26*$E26 -> 0 | AR26: =AQ26*$E26 -> 0 | AT26: =AS26*$E26 -> 0 | AV26: =AU26*$E26 -> 0 | AX26: =AW26*$E26 -> 0 | AZ26: =AY26*$E26 -> 0 | BB26: =BA26*$E26 -> 0 | BD26: =BC26*$E26 -> 0 | BF26: =BE26*$E26 -> 0 | BH26: =BG26*$E26 -> 0 | BJ26: =BI26*$E26 -> 0 | BL26: =BK26*$E26 -> 0
B27: =IF(ISBLANK($E27)," ",IF(AND(COUNTA(E$8:$E27)+64>72,COUNTA(E$8:$E27)+64<78),CHAR(COUNTA(E$8:$E27)+65),IF(COUNTA(E$8:$E27)+64>77,CHAR(COUNTA(E$8:$E27)+66),CHAR(COUNTA(E$8:$E27)+64)))) -> K | C27: PA-02G - Porcelain tile 365x1200x20mm ( L05 - Pool and paving steps tread) | D27: m2 | E27: 15 | F27: 288 | G27: 4320 | H27: 890 | I27: 15 | J27: =H27*$I27 -> 13350 | L27: =K27*$E27 -> 0 | N27: =M27*$E27 -> 0 | P27: =O27*$E27 -> 0 | Q27: 410 | R27: =Q27*$E27 -> 6150 | T27: =S27*$E27 -> 0 | U27: 363 | V27: 15 | W27: =V27*U27 -> 5445 | Y27: =X27*$E27 -> 0 | AA27: =Z27*$E27 -> 0 | AC27: =AB27*$E27 -> 0 | AE27: =AD27*$E27 -> 0 | AF27: 572 | AG27: 15 | AH27: =AF27*$AG27 -> 8580 | AJ27: =AI27*$E27 -> 0 | AL27: =AK27*$E27 -> 0 | AN27: =AM27*$E27 -> 0 | AP27: =AO27*$E27 -> 0 | AR27: =AQ27*$E27 -> 0 | AT27: =AS27*$E27 -> 0 | AV27: =AU27*$E27 -> 0 | AX27: =AW27*$E27 -> 0 | AZ27: =AY27*$E27 -> 0 | BB27: =BA27*$E27 -> 0 | BD27: =BC27*$E27 -> 0 | BF27: =BE27*$E27 -> 0 | BH27: =BG27*$E27 -> 0 | BJ27: =BI27*$E27 -> 0 | BL27: =BK27*$E27 -> 0
B28: =IF(ISBLANK($E28)," ",IF(AND(COUNTA(E$8:$E28)+64>72,COUNTA(E$8:$E28)+64<78),CHAR(COUNTA(E$8:$E28)+65),IF(COUNTA(E$8:$E28)+64>77,CHAR(COUNTA(E$8:$E28)+66),CHAR(COUNTA(E$8:$E28)+64)))) -> L | C28: PA-02H - Porcelain tile 300x1200x20mm (L05 - Pool steps tread) | D28: m2 | E28: 35.5 | F28: 313.2 | G28: 11275.2 | H28: 570 | I28: 36 | J28: =H28*$I28 -> 20520 | L28: =K28*$E28 -> 0 | N28: =M28*$E28 -> 0 | P28: =O28*$E28 -> 0 | Q28: 410 | R28: =Q28*$E28 -> 14555 | T28: =S28*$E28 -> 0 | U28: 439 | V28: 36 | W28: =V28*U28 -> 15804 | Y28: =X28*$E28 -> 0 | AA28: =Z28*$E28 -> 0 | AC28: =AB28*$E28 -> 0 | AE28: =AD28*$E28 -> 0 | AG28: 35.5 | AH28: =AF28*$AG28 -> 0 | AJ28: =AI28*$E28 -> 0 | AL28: =AK28*$E28 -> 0 | AN28: =AM28*$E28 -> 0 | AP28: =AO28*$E28 -> 0 | AR28: =AQ28*$E28 -> 0 | AT28: =AS28*$E28 -> 0 | AV28: =AU28*$E28 -> 0 | AX28: =AW28*$E28 -> 0 | AZ28: =AY28*$E28 -> 0 | BB28: =BA28*$E28 -> 0 | BD28: =BC28*$E28 -> 0 | BF28: =BE28*$E28 -> 0 | BH28: =BG28*$E28 -> 0 | BJ28: =BI28*$E28 -> 0 | BL28: =BK28*$E28 -> 0
B29: =IF(ISBLANK($E29)," ",IF(AND(COUNTA(E$8:$E29)+64>72,COUNTA(E$8:$E29)+64<78),CHAR(COUNTA(E$8:$E29)+65),IF(COUNTA(E$8:$E29)+64>77,CHAR(COUNTA(E$8:$E29)+66),CHAR(COUNTA(E$8:$E29)+64)))) -> M | C29: PA-02I - Porcelain tile 300x300x10mm (L05 - TT table base) | D29: m2 | E29: 4.3 | F29: 233.1 | G29: 932.4 | H29: 890 | I29: 4 | J29: =H29*$I29 -> 3560 | L29: =K29*$E29 -> 0 | N29: =M29*$E29 -> 0 | P29: =O29*$E29 -> 0 | Q29: 380 | R29: =Q29*$E29 -> 1634 | T29: =S29*$E29 -> 0 | U29: 294 | V29: 5 | W29: =V29*U29 -> 1470 | Y29: =X29*$E29 -> 0 | AA29: =Z29*$E29 -> 0 | AC29: =AB29*$E29 -> 0 | AE29: =AD29*$E29 -> 0 | AF29: 418 | AG29: 4.3 | AH29: =AF29*$AG29 -> 1797.4 | AJ29: =AI29*$E29 -> 0 | AL29: =AK29*$E29 -> 0 | AN29: =AM29*$E29 -> 0 | AP29: =AO29*$E29 -> 0 | AR29: =AQ29*$E29 -> 0 | AT29: =AS29*$E29 -> 0 | AV29: =AU29*$E29 -> 0 | AX29: =AW29*$E29 -> 0 | AZ29: =AY29*$E29 -> 0 | BB29: =BA29*$E29 -> 0 | BD29: =BC29*$E29 -> 0 | BF29: =BE29*$E29 -> 0 | BH29: =BG29*$E29 -> 0 | BJ29: =BI29*$E29 -> 0 | BL29: =BK29*$E29 -> 0
B30: =IF(ISBLANK($E30)," ",IF(AND(COUNTA(E$8:$E30)+64>72,COUNTA(E$8:$E30)+64<78),CHAR(COUNTA(E$8:$E30)+65),IF(COUNTA(E$8:$E30)+64>77,CHAR(COUNTA(E$8:$E30)+66),CHAR(COUNTA(E$8:$E30)+64)))) -> N | C30: PA-03 - Pea Gravel - Greige | D30: m2 | E30: 184 | F30: 73.8 | G30: 13579.2 | H30: 166 | I30: 184 | J30: =H30*$I30 -> 30544 | L30: =K30*$E30 -> 0 | N30: =M30*$E30 -> 0 | P30: =O30*$E30 -> 0 | Q30: 185 | R30: =Q30*$E30 -> 34040 | T30: =S30*$E30 -> 0 | U30: 134 | V30: 184 | W30: =V30*U30 -> 24656 | Y30: =X30*$E30 -> 0 | AA30: =Z30*$E30 -> 0 | AC30: =AB30*$E30 -> 0 | AE30: =AD30*$E30 -> 0 | AF30: 152 | AG30: 184 | AH30: =AF30*$AG30 -> 27968 | AJ30: =AI30*$E30 -> 0 | AL30: =AK30*$E30 -> 0 | AN30: =AM30*$E30 -> 0 | AP30: =AO30*$E30 -> 0 | AR30: =AQ30*$E30 -> 0 | AT30: =AS30*$E30 -> 0 | AV30: =AU30*$E30 -> 0 | AX30: =AW30*$E30 -> 0 | AZ30: =AY30*$E30 -> 0 | BB30: =BA30*$E30 -> 0 | BD30: =BC30*$E30 -> 0 | BF30: =BE30*$E30 -> 0 | BH30: =BG30*$E30 -> 0 | BJ30: =BI30*$E30 -> 0 | BL30: =BK30*$E30 -> 0
B31: =IF(ISBLANK($E31)," ",IF(AND(COUNTA(E$8:$E31)+64>72,COUNTA(E$8:$E31)+64<78),CHAR(COUNTA(E$8:$E31)+65),IF(COUNTA(E$8:$E31)+64>77,CHAR(COUNTA(E$8:$E31)+66),CHAR(COUNTA(E$8:$E31)+64)))) -> P | C31: PA-04 - Composite bamboo decking 1850x125x20mm | D31: m2 | E31: 49 | F31: 575.1 | G31: 82239.3 | H31: 1049 | I31: 49 | J31: =H31*$I31 -> 51401 | L31: =K31*$E31 -> 0 | N31: =M31*$E31 -> 0 | P31: =O31*$E31 -> 0 | Q31: 625 | R31: =Q31*$E31 -> 30625 | T31: =S31*$E31 -> 0 | U31: 735 | V31: 143 | W31: =V31*U31 -> 105105 | Y31: =X31*$E31 -> 0 | AA31: =Z31*$E31 -> 0 | AC31: =AB31*$E31 -> 0 | AE31: =AD31*$E31 -> 0 | AF31: 1067 | AG31: 49 | AH31: =AF31*$AG31 -> 52283 | AJ31: =AI31*$E31 -> 0 | AL31: =AK31*$E31 -> 0 | AN31: =AM31*$E31 -> 0 | AP31: =AO31*$E31 -> 0 | AR31: =AQ31*$E31 -> 0 | AT31: =AS31*$E31 -> 0 | AV31: =AU31*$E31 -> 0 | AX31: =AW31*$E31 -> 0 | AZ31: =AY31*$E31 -> 0 | BB31: =BA31*$E31 -> 0 | BD31: =BC31*$E31 -> 0 | BF31: =BE31*$E31 -> 0 | BH31: =BG31*$E31 -> 0 | BJ31: =BI31*$E31 -> 0 | BL31: =BK31*$E31 -> 0
B32: =IF(ISBLANK($E32)," ",IF(AND(COUNTA(E$8:$E32)+64>72,COUNTA(E$8:$E32)+64<78),CHAR(COUNTA(E$8:$E32)+65),IF(COUNTA(E$8:$E32)+64>77,CHAR(COUNTA(E$8:$E32)+66),CHAR(COUNTA(E$8:$E32)+64)))) -> Q | C32: PA-05 - TPV sports Flooring 10mm (L01 - Kids play area Activity zone Outdoor Gym) | D32: m2 | E32: 154 | F32: 520.2 | G32: 80110.8 | H32: 964 | I32: 154 | J32: =H32*$I32 -> 148456 | L32: =K32*$E32 -> 0 | N32: =M32*$E32 -> 0 | P32: =O32*$E32 -> 0 | Q32: 625 | R32: =Q32*$E32 -> 96250 | T32: =S32*$E32 -> 0 | U32: 708 | V32: 154 | W32: =V32*U32 -> 109032 | Y32: =X32*$E32 -> 0 | AA32: =Z32*$E32 -> 0 | AC32: =AB32*$E32 -> 0 | AE32: =AD32*$E32 -> 0 | AF32: 707 | AG32: 154 | AH32: =AF32*$AG32 -> 108878 | AJ32: =AI32*$E32 -> 0 | AL32: =AK32*$E32 -> 0 | AN32: =AM32*$E32 -> 0 | AP32: =AO32*$E32 -> 0 | AR32: =AQ32*$E32 -> 0 | AT32: =AS32*$E32 -> 0 | AV32: =AU32*$E32 -> 0 | AX32: =AW32*$E32 -> 0 | AZ32: =AY32*$E32 -> 0 | BB32: =BA32*$E32 -> 0 | BD32: =BC32*$E32 -> 0 | BF32: =BE32*$E32 -> 0 | BH32: =BG32*$E32 -> 0 | BJ32: =BI32*$E32 -> 0 | BL32: =BK32*$E32 -> 0
B33: =IF(ISBLANK($E33)," ",IF(AND(COUNTA(E$8:$E33)+64>72,COUNTA(E$8:$E33)+64<78),CHAR(COUNTA(E$8:$E33)+65),IF(COUNTA(E$8:$E33)+64>77,CHAR(COUNTA(E$8:$E33)+66),CHAR(COUNTA(E$8:$E33)+64)))) -> R | C33: PA-06 - Decorative Concrete flooring (L01 - Outdoor Dining Area) | D33: m2 | E33: 74 | F33: 684.9 | G33: 51367.5 | H33: 1006 | I33: 74 | J33: =H33*$I33 -> 74444 | L33: =K33*$E33 -> 0 | N33: =M33*$E33 -> 0 | P33: =O33*$E33 -> 0 | Q33: 450 | R33: =Q33*$E33 -> 33300 | T33: =S33*$E33 -> 0 | U33: 863 | V33: 75 | W33: =V33*U33 -> 64725 | Y33: =X33*$E33 -> 0 | AA33: =Z33*$E33 -> 0 | AC33: =AB33*$E33 -> 0 | AE33: =AD33*$E33 -> 0 | AF33: 427 | AG33: 74 | AH33: =AF33*$AG33 -> 31598 | AJ33: =AI33*$E33 -> 0 | AL33: =AK33*$E33 -> 0 | AN33: =AM33*$E33 -> 0 | AP33: =AO33*$E33 -> 0 | AR33: =AQ33*$E33 -> 0 | AT33: =AS33*$E33 -> 0 | AV33: =AU33*$E33 -> 0 | AX33: =AW33*$E33 -> 0 | AZ33: =AY33*$E33 -> 0 | BB33: =BA33*$E33 -> 0 | BD33: =BC33*$E33 -> 0 | BF33: =BE33*$E33 -> 0 | BH33: =BG33*$E33 -> 0 | BJ33: =BI33*$E33 -> 0 | BL33: =BK33*$E33 -> 0
B34: =IF(ISBLANK($E34)," ",IF(AND(COUNTA(E$8:$E34)+64>72,COUNTA(E$8:$E34)+64<78),CHAR(COUNTA(E$8:$E34)+65),IF(COUNTA(E$8:$E34)+64>77,CHAR(COUNTA(E$8:$E34)+66),CHAR(COUNTA(E$8:$E34)+64)))) -> S | C34: PA-07A - Natural stone banding - Honed 200x200x30mm | D34: m2 | E34: 12 | F34: 384.3 | G34: 4995.9 | H34: 959 | I34: 12 | J34: =H34*$I34 -> 11508 | L34: =K34*$E34 -> 0 | N34: =M34*$E34 -> 0 | P34: =O34*$E34 -> 0 | Q34: 620 | R34: =Q34*$E34 -> 7440 | T34: =S34*$E34 -> 0 | U34: 666 | V34: 13 | W34: =V34*U34 -> 8658 | Y34: =X34*$E34 -> 0 | AA34: =Z34*$E34 -> 0 | AC34: =AB34*$E34 -> 0 | AE34: =AD34*$E34 -> 0 | AF34: 572 | AG34: 12 | AH34: =AF34*$AG34 -> 6864 | AJ34: =AI34*$E34 -> 0 | AL34: =AK34*$E34 -> 0 | AN34: =AM34*$E34 -> 0 | AP34: =AO34*$E34 -> 0 | AR34: =AQ34*$E34 -> 0 | AT34: =AS34*$E34 -> 0 | AV34: =AU34*$E34 -> 0 | AX34: =AW34*$E34 -> 0 | AZ34: =AY34*$E34 -> 0 | BB34: =BA34*$E34 -> 0 | BD34: =BC34*$E34 -> 0 | BF34: =BE34*$E34 -> 0 | BH34: =BG34*$E34 -> 0 | BJ34: =BI34*$E34 -> 0 | BL34: =BK34*$E34 -> 0
B35: =IF(ISBLANK($E35)," ",IF(AND(COUNTA(E$8:$E35)+64>72,COUNTA(E$8:$E35)+64<78),CHAR(COUNTA(E$8:$E35)+65),IF(COUNTA(E$8:$E35)+64>77,CHAR(COUNTA(E$8:$E35)+66),CHAR(COUNTA(E$8:$E35)+64)))) -> T | C35: PA-07B - Natural stone flooring - Flamed 100x100x30mm | D35: m2 | E35: 64 | F35: 524.7 | G35: 33580.8 | H35: 1002 | I35: 64 | J35: =H35*$I35 -> 64128 | L35: =K35*$E35 -> 0 | N35: =M35*$E35 -> 0 | P35: =O35*$E35 -> 0 | Q35: 620 | R35: =Q35*$E35 -> 39680 | T35: =S35*$E35 -> 0 | U35: 775 | V35: 64 | W35: =V35*U35 -> 49600 | Y35: =X35*$E35 -> 0 | AA35: =Z35*$E35 -> 0 | AC35: =AB35*$E35 -> 0 | AE35: =AD35*$E35 -> 0 | AF35: 628 | AG35: 64 | AH35: =AF35*$AG35 -> 40192 | AJ35: =AI35*$E35 -> 0 | AL35: =AK35*$E35 -> 0 | AN35: =AM35*$E35 -> 0 | AP35: =AO35*$E35 -> 0 | AR35: =AQ35*$E35 -> 0 | AT35: =AS35*$E35 -> 0 | AV35: =AU35*$E35 -> 0 | AX35: =AW35*$E35 -> 0 | AZ35: =AY35*$E35 -> 0 | BB35: =BA35*$E35 -> 0 | BD35: =BC35*$E35 -> 0 | BF35: =BE35*$E35 -> 0 | BH35: =BG35*$E35 -> 0 | BJ35: =BI35*$E35 -> 0 | BL35: =BK35*$E35 -> 0
B36: =IF(ISBLANK($E36)," ",IF(AND(COUNTA(E$8:$E36)+64>72,COUNTA(E$8:$E36)+64<78),CHAR(COUNTA(E$8:$E36)+65),IF(COUNTA(E$8:$E36)+64>77,CHAR(COUNTA(E$8:$E36)+66),CHAR(COUNTA(E$8:$E36)+64)))) -> U | C36: PA-08 - Silica sand (pet play sand) (L01 - Pet play area) | D36: m2 | E36: 39 | F36: 242.1 | G36: 9684 | H36: 151 | I36: 39 | J36: =H36*$I36 -> 5889 | L36: =K36*$E36 -> 0 | N36: =M36*$E36 -> 0 | P36: =O36*$E36 -> 0 | Q36: 320 | R36: =Q36*$E36 -> 12480 | T36: =S36*$E36 -> 0 | U36: 305 | V36: 40 | W36: =V36*U36 -> 12200 | Y36: =X36*$E36 -> 0 | AA36: =Z36*$E36 -> 0 | AC36: =AB36*$E36 -> 0 | AE36: =AD36*$E36 -> 0 | AF36: 399 | AG36: 39 | AH36: =AF36*$AG36 -> 15561 | AJ36: =AI36*$E36 -> 0 | AL36: =AK36*$E36 -> 0 | AN36: =AM36*$E36 -> 0 | AP36: =AO36*$E36 -> 0 | AR36: =AQ36*$E36 -> 0 | AT36: =AS36*$E36 -> 0 | AV36: =AU36*$E36 -> 0 | AX36: =AW36*$E36 -> 0 | AZ36: =AY36*$E36 -> 0 | BB36: =BA36*$E36 -> 0 | BD36: =BC36*$E36 -> 0 | BF36: =BE36*$E36 -> 0 | BH36: =BG36*$E36 -> 0 | BJ36: =BI36*$E36 -> 0 | BL36: =BK36*$E36 -> 0
B37: =IF(ISBLANK($E37)," ",IF(AND(COUNTA(E$35:$E37)+64>72,COUNTA(E$35:$E37)+64<78),CHAR(COUNTA(E$35:$E37)+65),IF(COUNTA(E$35:$E37)+64>77,CHAR(COUNTA(E$35:$E37)+66),CHAR(COUNTA(E$35:$E37)+64)))) -> C | C37: PA-09 - River pebble - Semi polished.(L05 -Adult Pool Overflow edge) | D37: m2 | E37: 46 | F37: 165.6 | G37: 7617.6 | H37: 457 | I37: 46 | J37: =H37*$I37 -> 21022 | L37: =K37*$E37 -> 0 | N37: =M37*$E37 -> 0 | P37: =O37*$E37 -> 0 | Q37: 410 | R37: =Q37*$E37 -> 18860 | T37: =S37*$E37 -> 0 | U37: 287 | V37: 46 | W37: =V37*U37 -> 13202 | Y37: =X37*$E37 -> 0 | AA37: =Z37*$E37 -> 0 | AC37: =AB37*$E37 -> 0 | AE37: =AD37*$E37 -> 0 | AG37: 46 | AH37: =AF37*$AG37 -> 0 | AJ37: =AI37*$E37 -> 0 | AL37: =AK37*$E37 -> 0 | AN37: =AM37*$E37 -> 0 | AP37: =AO37*$E37 -> 0 | AR37: =AQ37*$E37 -> 0 | AT37: =AS37*$E37 -> 0 | AV37: =AU37*$E37 -> 0 | AX37: =AW37*$E37 -> 0 | AZ37: =AY37*$E37 -> 0 | BB37: =BA37*$E37 -> 0 | BD37: =BC37*$E37 -> 0 | BF37: =BE37*$E37 -> 0 | BH37: =BG37*$E37 -> 0 | BJ37: =BI37*$E37 -> 0 | BL37: =BK37*$E37 -> 0
B38: =IF(ISBLANK($E38)," ",IF(AND(COUNTA(E$35:$E38)+64>72,COUNTA(E$35:$E38)+64<78),CHAR(COUNTA(E$35:$E38)+65),IF(COUNTA(E$35:$E38)+64>77,CHAR(COUNTA(E$35:$E38)+66),CHAR(COUNTA(E$35:$E38)+64)))) -> D | C38: W-01 - Wall coping tile 200x600x20 | D38: m | E38: 423 | F38: 84.6 | G38: 45514.8 | H38: 752 | I38: 423 | J38: =H38*$I38 -> 318096 | L38: =K38*$E38 -> 0 | N38: =M38*$E38 -> 0 | P38: =O38*$E38 -> 0 | Q38: 385 | R38: =Q38*$E38 -> 162855 | T38: =S38*$E38 -> 0 | U38: 106 | V38: 538 | W38: =V38*U38 -> 57028 | Y38: =X38*$E38 -> 0 | AA38: =Z38*$E38 -> 0 | AC38: =AB38*$E38 -> 0 | AE38: =AD38*$E38 -> 0 | AF38: 188 | AG38: 423 | AH38: =AF38*$AG38 -> 79524 | AJ38: =AI38*$E38 -> 0 | AL38: =AK38*$E38 -> 0 | AN38: =AM38*$E38 -> 0 | AP38: =AO38*$E38 -> 0 | AR38: =AQ38*$E38 -> 0 | AT38: =AS38*$E38 -> 0 | AV38: =AU38*$E38 -> 0 | AX38: =AW38*$E38 -> 0 | AZ38: =AY38*$E38 -> 0 | BB38: =BA38*$E38 -> 0 | BD38: =BC38*$E38 -> 0 | BF38: =BE38*$E38 -> 0 | BH38: =BG38*$E38 -> 0 | BJ38: =BI38*$E38 -> 0 | BL38: =BK38*$E38 -> 0
B39: =IF(ISBLANK($E39)," ",IF(AND(COUNTA(E$35:$E39)+64>72,COUNTA(E$35:$E39)+64<78),CHAR(COUNTA(E$35:$E39)+65),IF(COUNTA(E$35:$E39)+64>77,CHAR(COUNTA(E$35:$E39)+66),CHAR(COUNTA(E$35:$E39)+64)))) -> E | C39: W-02 - Porcelain wall tile 600x600x10mm | D39: m2 | E39: 320 | F39: 249.3 | G39: 79776 | H39: 458 | I39: 320 | J39: =H39*$I39 -> 146560 | L39: =K39*$E39 -> 0 | N39: =M39*$E39 -> 0 | P39: =O39*$E39 -> 0 | Q39: 385 | R39: =Q39*$E39 -> 123200 | T39: =S39*$E39 -> 0 | U39: 329 | V39: 320 | W39: =V39*U39 -> 105280 | Y39: =X39*$E39 -> 0 | AA39: =Z39*$E39 -> 0 | AC39: =AB39*$E39 -> 0 | AE39: =AD39*$E39 -> 0 | AF39: 404 | AG39: 320 | AH39: =AF39*$AG39 -> 129280 | AJ39: =AI39*$E39 -> 0 | AL39: =AK39*$E39 -> 0 | AN39: =AM39*$E39 -> 0 | AP39: =AO39*$E39 -> 0 | AR39: =AQ39*$E39 -> 0 | AT39: =AS39*$E39 -> 0 | AV39: =AU39*$E39 -> 0 | AX39: =AW39*$E39 -> 0 | AZ39: =AY39*$E39 -> 0 | BB39: =BA39*$E39 -> 0 | BD39: =BC39*$E39 -> 0 | BF39: =BE39*$E39 -> 0 | BH39: =BG39*$E39 -> 0 | BJ39: =BI39*$E39 -> 0 | BL39: =BK39*$E39 -> 0
B40: ADD | C40: W-02 - Porcelain wall tile 600x600x10mm | D40: m2 | E40: 8 | R40: =Q40*$E40 -> 0 | T40: =S40*$E40 -> 0 | U40: 328 | V40: 8 | W40: =V40*U40 -> 2624 | AF40: 572 | AG40: 8 | AH40: =AF40*$AG40 -> 4576
B41: =IF(ISBLANK($E41)," ",IF(AND(COUNTA(E$35:$E41)+64>72,COUNTA(E$35:$E41)+64<78),CHAR(COUNTA(E$35:$E41)+65),IF(COUNTA(E$35:$E41)+64>77,CHAR(COUNTA(E$35:$E41)+66),CHAR(COUNTA(E$35:$E41)+64)))) -> G | C41: WA-01 - Outdoor wallpaper (kids play area) | D41: m | E41: 18 | F41: 3427.2 | G41: 61689.6 | I41: 18 | J41: =H41*$I41 -> 0 | L41: =K41*$E41 -> 0 | N41: =M41*$E41 -> 0 | P41: =O41*$E41 -> 0 | Q41: 795 | R41: =Q41*$E41 -> 14310 | T41: =S41*$E41 -> 0 | V41: 18 | W41: =V41*U41 -> 0 | Y41: =X41*$E41 -> 0 | AA41: =Z41*$E41 -> 0 | AC41: =AB41*$E41 -> 0 | AE41: =AD41*$E41 -> 0 | AG41: 18 | AH41: =AF41*$AG41 -> 0 | AJ41: =AI41*$E41 -> 0 | AL41: =AK41*$E41 -> 0 | AN41: =AM41*$E41 -> 0 | AP41: =AO41*$E41 -> 0 | AR41: =AQ41*$E41 -> 0 | AT41: =AS41*$E41 -> 0 | AV41: =AU41*$E41 -> 0 | AX41: =AW41*$E41 -> 0 | AZ41: =AY41*$E41 -> 0 | BB41: =BA41*$E41 -> 0 | BD41: =BC41*$E41 -> 0 | BF41: =BE41*$E41 -> 0 | BH41: =BG41*$E41 -> 0 | BJ41: =BI41*$E41 -> 0 | BL41: =BK41*$E41 -> 0
B42: =IF(ISBLANK($E42)," ",IF(AND(COUNTA(E$35:$E42)+64>72,COUNTA(E$35:$E42)+64<78),CHAR(COUNTA(E$35:$E42)+65),IF(COUNTA(E$35:$E42)+64>77,CHAR(COUNTA(E$35:$E42)+66),CHAR(COUNTA(E$35:$E42)+64)))) -> H | C42: WA-02 - Graffiti Art | D42: m | E42: 18 | F42: 225 | G42: 4050 | I42: 18 | J42: =H42*$I42 -> 0 | L42: =K42*$E42 -> 0 | N42: =M42*$E42 -> 0 | P42: =O42*$E42 -> 0 | Q42: 1200 | R42: =Q42*$E42 -> 21600 | T42: =S42*$E42 -> 0 | V42: 8 | W42: =V42*U42 -> 0 | Y42: =X42*$E42 -> 0 | AA42: =Z42*$E42 -> 0 | AC42: =AB42*$E42 -> 0 | AE42: =AD42*$E42 -> 0 | AG42: 18 | AH42: =AF42*$AG42 -> 0 | AJ42: =AI42*$E42 -> 0 | AL42: =AK42*$E42 -> 0 | AN42: =AM42*$E42 -> 0 | AP42: =AO42*$E42 -> 0 | AR42: =AQ42*$E42 -> 0 | AT42: =AS42*$E42 -> 0 | AV42: =AU42*$E42 -> 0 | AX42: =AW42*$E42 -> 0 | AZ42: =AY42*$E42 -> 0 | BB42: =BA42*$E42 -> 0 | BD42: =BC42*$E42 -> 0 | BF42: =BE42*$E42 -> 0 | BH42: =BG42*$E42 -> 0 | BJ42: =BI42*$E42 -> 0 | BL42: =BK42*$E42 -> 0
B43: =IF(ISBLANK($E43)," ",IF(AND(COUNTA(E$35:$E43)+64>72,COUNTA(E$35:$E43)+64<78),CHAR(COUNTA(E$35:$E43)+65),IF(COUNTA(E$35:$E43)+64>77,CHAR(COUNTA(E$35:$E43)+66),CHAR(COUNTA(E$35:$E43)+64)))) -> J | C43: F-01 - Treated timber | D43: m2 | E43: 44 | F43: 2621.7 | G43: 44568.9 | H43: 1100 | I43: 44 | J43: =H43*$I43 -> 48400 | L43: =K43*$E43 -> 0 | N43: =M43*$E43 -> 0 | P43: =O43*$E43 -> 0 | Q43: 725 | R43: =Q43*$E43 -> 31900 | T43: =S43*$E43 -> 0 | U43: 3306 | V43: 17 | W43: =V43*U43 -> 56202 | Y43: =X43*$E43 -> 0 | AA43: =Z43*$E43 -> 0 | AC43: =AB43*$E43 -> 0 | AE43: =AD43*$E43 -> 0 | AF43: 934 | AG43: 44 | AH43: =AF43*$AG43 -> 41096 | AJ43: =AI43*$E43 -> 0 | AL43: =AK43*$E43 -> 0 | AN43: =AM43*$E43 -> 0 | AP43: =AO43*$E43 -> 0 | AR43: =AQ43*$E43 -> 0 | AT43: =AS43*$E43 -> 0 | AV43: =AU43*$E43 -> 0 | AX43: =AW43*$E43 -> 0 | AZ43: =AY43*$E43 -> 0 | BB43: =BA43*$E43 -> 0 | BD43: =BC43*$E43 -> 0 | BF43: =BE43*$E43 -> 0 | BH43: =BG43*$E43 -> 0 | BJ43: =BI43*$E43 -> 0 | BL43: =BK43*$E43 -> 0
...
